[33mWARNING [0m urllib3.connectionpool:connectionpool.py:812 Retrying (Retry(total=2, connect=None, read=None, redirect=None, status=None)) after connection broken by 'NewConnectionError('<urllib3.connection.HTTPConnection object at 0x000002271168D6F0>: Failed to establish a new connection: [Errno 11001] getaddrinfo failed')': //192.168.1.252:4444/wd/hub:4444/wd/hub/session
[33mWARNING [0m urllib3.connectionpool:connectionpool.py:812 Retrying (Retry(total=1, connect=None, read=None, redirect=None, status=None)) after connection broken by 'NewConnectionError('<urllib3.connection.HTTPConnection object at 0x000002271168DAB0>: Failed to establish a new connection: [Errno 11001] getaddrinfo failed')': //192.168.1.252:4444/wd/hub:4444/wd/hub/session
[33mWARNING [0m urllib3.connectionpool:connectionpool.py:812 Retrying (Retry(total=0, connect=None, read=None, redirect=None, status=None)) after connection broken by 'NewConnectionError('<urllib3.connection.HTTPConnection object at 0x000002271168DBA0>: Failed to establish a new connection: [Errno 11001] getaddrinfo failed')': //192.168.1.252:4444/wd/hub:4444/wd/hub/session